Workbook

Sheet PNL
H1: План (приклад) | J1: Факт
A2: Стаття | B2: Показник | C2: % | D2: Показник | E2: % | F2: Показник | G2: % | H2: Показник | I2: % | J2: Показник | K2: % | L2: Показник | M2: % | N2: Показник | O2: % | P2: Показник | Q2: % | R2: Показник | S2: % | T2: Показник | U2: % | V2: Показник | W2: % | X2: Показник | Y2: % | Z2: Показник | AA2: % | AB2: Показник | AC2: % | AD2: Показник | AE2: % | AF2: Показник | AG2: % | AH2: Показник | AI2: %
B3: листопад | D3: грудень | F3: січень | H3: березень | L3: квітень | N3: травень | P3: Червень | R3: Липень | T3: Серпень | V3: Вересень | X3: Жовтень | Z3: Серпень | AB3: Вересень | AD3: Жовтень | AF3: Листопад | AH3: Грудень
A4: Валові продажі (gross sales) | B4: =#REF! -> #REF! | C4: =#REF! -> #REF! | D4: =#REF! -> #REF! | E4: =#REF! -> #REF! | F4: =#REF! -> #REF! | G4: =#REF! -> #REF! | H4: =73*2.5*35*30.5 -> 194818.75 | I4: =H4/H4 -> 1 | J4: ='Загальний звіт'!D13 -> #REF! | K4: =J4/J4 -> #REF! | L4: ='Загальний звіт'!F13 -> #REF! | M4: ='Загальний звіт'!G13 -> #REF! | N4: ='Загальний звіт'!H13 -> #REF! | O4: ='Загальний звіт'!I13 -> #REF! | P4: ='Загальний звіт'!J13 -> #REF! | Q4: ='Загальний звіт'!K13 -> #REF! | R4: ='Загальний звіт'!L13 -> #REF! | S4: ='Загальний звіт'!M13 -> #REF! | ... Y4: ='Загальний звіт'!S13 -> #REF! | Z4: ='Загальний звіт'!N13 -> #REF! | AA4: ='Загальний звіт'!O13 -> #REF! | AB4: ='Загальний звіт'!P13 -> #REF! | AC4: ='Загальний звіт'!Q13 -> #REF! | AD4: ='Загальний звіт'!R13 -> #REF! | AE4: ='Загальний звіт'!S13 -> #REF! | AF4: ='Загальний звіт'!T13 -> #REF! | AG4: ='Загальний звіт'!U13 -> #REF! | ... AI4: ='Загальний звіт'!W13 -> #REF!
A5: ПДВ+акциз | B5: =#REF! -> #REF! | C5: =#REF! -> #REF! | D5: =#REF! -> #REF! | E5: =#REF! -> #REF! | F5: =#REF! -> #REF! | G5: =#REF! -> #REF! | H5: 15000 | I5: =H5/H4 -> 0.076994642 | J5: ='Загальний звіт'!D18 -> #REF! | K5: =J5/J4 -> #REF! | L5: ='Загальний звіт'!F18 -> #REF! | M5: =L5/L4 -> #REF! | N5: ='Загальний звіт'!H18 -> #REF! | O5: =N5/N4 -> #REF! | P5: ='Загальний звіт'!J18 -> #REF! | Q5: =P5/P4 -> #REF! | R5: ='Загальний звіт'!L18 -> #REF! | S5: =R5/R4 -> #REF! | T5: ='Загальний звіт'!N18 -> #REF! | U5: =T5/T4 -> #REF! | V5: ='Загальний звіт'!P18 -> #REF! | W5: =V5/V4 -> #REF! | X5: ='Загальний звіт'!R18 -> #REF! | Y5: =X5/X4 -> #REF! | Z5: ='Загальний звіт'!N18 -> #REF! | AA5: ='Загальний звіт'!O18 -> #REF! | AB5: ='Загальний звіт'!P18 -> #REF! | AC5: ='Загальний звіт'!Q18 -> #REF! | AD5: ='Загальний звіт'!R18 -> #REF! | AE5: ='Загальний звіт'!S18 -> #REF! | AF5: ='Загальний звіт'!T18 -> #REF! | AG5: ='Загальний звіт'!U18 -> #REF! | ... AI5: ='Загальний звіт'!W18 -> #REF!
A6: Чисті продажі (net sales) | B6: =B4-B5 -> #REF! | C6: =C4-C5 -> #REF! | D6: =D4-D5 -> #REF! | E6: =E4-E5 -> #REF! | F6: =F4-F5 -> #REF! | G6: =G4-G5 -> #REF! | H6: =H4-H5 -> 179818.75 | I6: =H6/H4 -> 0.92300536 | J6: =J4-J5 -> #REF! | K6: =J6/J4 -> #REF! | L6: =L4-L5 -> #REF! | M6: =L6/L4 -> #REF! | N6: =N4-N5 -> #REF! | O6: =N6/N4 -> #REF! | P6: =P4-P5 -> #REF! | Q6: =P6/P4 -> #REF! | R6: =R4-R5 -> #REF! | S6: =R6/R4 -> #REF! | T6: =T4-T5 -> #REF! | U6: =T6/T4 -> #REF! | V6: =V4-V5 -> #REF! | W6: =V6/V4 -> #REF! | X6: =X4-X5 -> #REF! | Y6: =X6/X4 -> #REF! | Z6: =Z4-Z5 -> #REF! | AA6: =AA4-AA5 -> #REF! | AB6: =AB4-AB5 -> #REF! | AC6: =AC4-AC5 -> #REF! | AD6: =AD4-AD5 -> #REF! | AE6: =AE4-AE5 -> #REF! | AF6: =AF4-AF5 -> #REF! | AG6: =AG4-AG5 -> #REF! | ... AI6: =AI4-AI5 -> #REF!
A7: Закупки + списання (продукти та напої) | B7: =#REF! -> #REF! | C7: =#REF! -> #REF! | D7: =#REF! -> #REF! | E7: =#REF! -> #REF! | F7: =#REF! -> #REF! | G7: =#REF! -> #REF! | H7: =H6*0.25 -> 44954.688 | I7: =H7/H6 -> 0.25 | J7: ='Загальний звіт'!D31 -> #REF! | K7: =J7/J6 -> #REF! | L7: ='Загальний звіт'!F31 -> #REF! | M7: =L7/L6 -> #REF! | N7: ='Загальний звіт'!H31 -> #REF! | O7: =N7/N6 -> #REF! | P7: ='Загальний звіт'!J31 -> #REF! | Q7: =P7/P6 -> #REF! | R7: ='Загальний звіт'!L31 -> #REF! | S7: =R7/R4 -> #REF! | T7: ='Загальний звіт'!N31 -> #REF! | U7: =T7/T4 -> #REF! | V7: ='Загальний звіт'!P31 -> #REF! | W7: =V7/V4 -> #REF! | X7: ='Загальний звіт'!R31 -> #REF! | Y7: =X7/X4 -> #REF! | Z7: ='Загальний звіт'!N31 -> #REF! | AA7: ='Загальний звіт'!O31 -> #REF! | AB7: ='Загальний звіт'!P31 -> #REF! | AC7: ='Загальний звіт'!Q31 -> #REF! | AD7: ='Загальний звіт'!R31 -> #REF! | AE7: ='Загальний звіт'!S31 -> #REF! | AF7: ='Загальний звіт'!T31 -> #REF! | AG7: ='Загальний звіт'!U31 -> #REF! | ... AI7: ='Загальний звіт'!W31 -> #REF!
A8: Валовий прибуток | B8: =B6-B7 -> #REF! | C8: =C6-C7 -> #REF! | D8: =D6-D7 -> #REF! | E8: =E6-E7 -> #REF! | F8: =F6-F7 -> #REF! | G8: =G6-G7 -> #REF! | H8: =H6-H7 -> 134864.06 | I8: =H8/H6 -> 0.75 | J8: =J6-J7 -> #REF! | K8: =J8/J6 -> #REF! | L8: =L6-L7 -> #REF! | M8: =L8/L6 -> #REF! | N8: =N6-N7 -> #REF! | O8: =N8/N6 -> #REF! | P8: =P6-P7 -> #REF! | Q8: =P8/P6 -> #REF! | R8: =R6-R7 -> #REF! | S8: =R8/R6 -> #REF! | T8: =T6-T7 -> #REF! | U8: =T8/T6 -> #REF! | V8: =V6-V7 -> #REF! | W8: =V8/V6 -> #REF! | X8: =X6-X7 -> #REF! | Y8: =X8/X6 -> #REF! | Z8: =Z6-Z7 -> #REF! | AA8: =AA6-AA7 -> #REF! | AB8: =AB6-AB7 -> #REF! | AC8: =AC6-AC7 -> #REF! | AD8: =AD6-AD7 -> #REF! | AE8: =AE6-AE7 -> #REF! | AF8: =AF6-AF7 -> #REF! | AG8: =AG6-AG7 -> #REF! | ... AI8: =AI6-AI7 -> #REF!
A9: Labor cost (з податками) | B9: =#REF! -> #REF! | C9: =#REF! -> #REF! | D9: =#REF! -> #REF! | E9: =#REF! -> #REF! | F9: =#REF! -> #REF! | G9: =#REF! -> #REF! | H9: =H6*0.35 -> 62936.562 | I9: =H9/H6 -> 0.35 | J9: ='Загальний звіт'!D33 -> #REF! | K9: =J9/J6 -> #REF! | L9: ='Загальний звіт'!F33 -> #REF! | M9: =L9/L6 -> #REF! | N9: ='Загальний звіт'!H33 -> #REF! | O9: =N9/N6 -> #REF! | P9: ='Загальний звіт'!J33 -> #REF! | Q9: =P9/P6 -> #REF! | R9: ='Загальний звіт'!L33 -> #REF! | S9: =R9/R6 -> #REF! | T9: ='Загальний звіт'!N33 -> #REF! | U9: =T9/T6 -> #REF! | V9: ='Загальний звіт'!P33 -> #REF! | W9: =V9/V4 -> #REF! | X9: ='Загальний звіт'!R33 -> #REF! | Y9: =X9/X4 -> #REF! | Z9: ='Загальний звіт'!N33 -> #REF! | AA9: ='Загальний звіт'!O33 -> #REF! | AB9: ='Загальний звіт'!P33 -> #REF! | AC9: ='Загальний звіт'!Q33 -> #REF! | AD9: ='Загальний звіт'!R33 -> #REF! | AE9: ='Загальний звіт'!S33 -> #REF! | AF9: ='Загальний звіт'!T33 -> #REF! | AG9: ='Загальний звіт'!U33 -> #REF! | ... AI9: ='Загальний звіт'!W33 -> #REF!
A10: Оренда приміщення (без ПДВ) | B10: =#REF! -> #REF! | C10: =#REF! -> #REF! | D10: =#REF! -> #REF! | E10: =#REF! -> #REF! | F10: =#REF! -> #REF! | G10: =#REF! -> #REF! | H10: 6000 | I10: =H10/H6 -> 0.033366932 | J10: ='Загальний звіт'!D34 -> #REF! | K10: =J10/J6 -> #REF! | L10: ='Загальний звіт'!F34 -> #REF! | M10: =L10/L6 -> #REF! | N10: ='Загальний звіт'!H34 -> #REF! | O10: =N10/N6 -> #REF! | P10: ='Загальний звіт'!J34 -> #REF! | Q10: =P10/P6 -> #REF! | R10: ='Загальний звіт'!L34 -> #REF! | S10: =R10/R6 -> #REF! | T10: ='Загальний звіт'!N34 -> #REF! | U10: =T10/T6 -> #REF! | V10: ='Загальний звіт'!P34 -> #REF! | W10: =V10/V4 -> #REF! | X10: ='Загальний звіт'!R34 -> #REF! | Y10: =X10/X4 -> #REF! | Z10: ='Загальний звіт'!N34 -> #REF! | AA10: ='Загальний звіт'!O34 -> #REF! | AB10: ='Загальний звіт'!P34 -> #REF! | AC10: ='Загальний звіт'!Q34 -> #REF! | AD10: ='Загальний звіт'!R34 -> #REF! | AE10: ='Загальний звіт'!S34 -> #REF! | AF10: ='Загальний звіт'!T34 -> #REF! | AG10: ='Загальний звіт'!U34 -> #REF! | ... AI10: ='Загальний звіт'!W34 -> #REF!
A11: Комунальні платежі (без ПДВ) | B11: =#REF! -> #REF! | C11: =#REF! -> #REF! | D11: =#REF! -> #REF! | E11: =#REF! -> #REF! | F11: =#REF! -> #REF! | G11: =#REF! -> #REF! | H11: 1000 | I11: =H11/H6 -> 0.0055611553 | J11: ='Загальний звіт'!D35 -> #REF! | K11: =J11/J6 -> #REF! | L11: ='Загальний звіт'!F35 -> #REF! | M11: =L11/L6 -> #REF! | N11: ='Загальний звіт'!H35 -> #REF! | O11: =N11/N6 -> #REF! | P11: ='Загальний звіт'!J35 -> #REF! | Q11: =P11/P6 -> #REF! | R11: ='Загальний звіт'!L35 -> #REF! | S11: =R11/R6 -> #REF! | T11: ='Загальний звіт'!N35 -> #REF! | U11: =T11/T6 -> #REF! | V11: ='Загальний звіт'!P35 -> #REF! | W11: =V11/V4 -> #REF! | X11: ='Загальний звіт'!R35 -> #REF! | Y11: =X11/X4 -> #REF! | Z11: ='Загальний звіт'!N35 -> #REF! | AA11: ='Загальний звіт'!O35 -> #REF! | AB11: ='Загальний звіт'!P35 -> #REF! | AC11: ='Загальний звіт'!Q35 -> #REF! | AD11: ='Загальний звіт'!R35 -> #REF! | AE11: ='Загальний звіт'!S35 -> #REF! | AF11: ='Загальний звіт'!T35 -> #REF! | AG11: ='Загальний звіт'!U35 -> #REF! | ... AI11: ='Загальний звіт'!W35 -> #REF!
A12: Маркетинг | H12: =H6*0.02 -> 3596.375 | I12: =H12/H6 -> 0.02 | J12: ='Загальний звіт'!D36 -> #REF! | K12: =J12/J6 -> #REF! | L12: ='Загальний звіт'!F36 -> #REF! | M12: =L12/L6 -> #REF! | N12: ='Загальний звіт'!H36 -> #REF! | O12: =N12/N6 -> #REF! | P12: ='Загальний звіт'!J36 -> #REF! | Q12: =P12/P6 -> #REF! | R12: ='Загальний звіт'!L36 -> #REF! | S12: =R12/R6 -> #REF! | T12: ='Загальний звіт'!N36 -> #REF! | U12: =T12/T6 -> #REF! | V12: ='Загальний звіт'!P36 -> #REF! | W12: =V12/V4 -> #REF! | X12: ='Загальний звіт'!R36 -> #REF! | Y12: =X12/X4 -> #REF!
A13: Роялті | H13: =H6*0.05 -> 8990.9375 | I13: =H13/H6 -> 0.05 | K13: =J13/J6 -> #REF! | M13: =L13/L6 -> #REF! | O13: =N13/N6 -> #REF! | Q13: =P13/P6 -> #REF! | S13: =R13/R6 -> #REF! | U13: =T13/T6 -> #REF!
A14: Інші операційні витрати | B14: =#REF!+#REF! -> #REF! | C14: =#REF!+#REF! -> #REF! | D14: =#REF!+#REF! -> #REF! | E14: =#REF!+#REF! -> #REF! | F14: =#REF!+#REF! -> #REF! | G14: =#REF!+#REF! -> #REF! | H14: =H6*0.05 -> 8990.9375 | I14: =H14/H6 -> 0.05 | J14: ='Загальний звіт'!D37 -> #REF! | K14: =J14/J6 -> #REF! | L14: ='Загальний звіт'!F37 -> #REF! | M14: =L14/L6 -> #REF! | N14: ='Загальний звіт'!H37 -> #REF! | O14: =N14/N6 -> #REF! | P14: ='Загальний звіт'!J37 -> #REF! | Q14: =P14/P6 -> #REF! | R14: ='Загальний звіт'!L37 -> #REF! | S14: =R14/R6 -> #REF! | T14: ='Загальний звіт'!N37 -> #REF! | U14: =T14/T6 -> #REF! | V14: ='Загальний звіт'!P37 -> #REF! | W14: =V14/V4 -> #REF! | X14: ='Загальний звіт'!R37 -> #REF! | Y14: =X14/X4 -> #REF! | Z14: ='Загальний звіт'!N36+'Загальний звіт'!N37 -> #REF! | AA14: ='Загальний звіт'!O36+'Загальний звіт'!O37 -> #REF! | AB14: ='Загальний звіт'!P36+'Загальний звіт'!P37 -> #REF! | AC14: ='Загальний звіт'!Q36+'Загальний звіт'!Q37 -> #REF! | AD14: ='Загальний звіт'!R36+'Загальний звіт'!R37 -> #REF! | AE14: ='Загальний звіт'!S36+'Загальний звіт'!S37 -> #REF! | AF14: ='Загальний звіт'!T36+'Загальний звіт'!T37 -> #REF! | AG14: ='Загальний звіт'!U36+'Загальний звіт'!U37 -> #REF! | ... AI14: ='Загальний звіт'!W36+'Загальний звіт'!W37 -> #REF!
A15: Всього операційні витрати | B15: =B9+B10+B11+B14 -> #REF! | C15: =C9+C10+C11+C14 -> #REF! | D15: =D9+D10+D11+D14 -> #REF! | E15: =E9+E10+E11+E14 -> #REF! | F15: =F9+F10+F11+F14 -> #REF! | G15: =G9+G10+G11+G14 -> #REF! | H15: =H9+H10+H11+H12+H13+H14 -> 91514.812 | I15: =H15/H4 -> 0.46974335 | J15: =J9+J10+J11+J12+J13+J14 -> #REF! | K15: =J15/J4 -> #REF! | L15: =L9+L10+L11+L12+L13+L14 -> #REF! | M15: =L15/L4 -> #REF! | N15: =N9+N10+N11+N12+N13+N14 -> #REF! | O15: =N15/N4 -> #REF! | P15: =P9+P10+P11+P12+P13+P14 -> #REF! | Q15: =P15/P4 -> #REF! | R15: =R9+R10+R11+R14 -> #REF! | S15: =R15/R4 -> #REF! | T15: =T9+T10+T11+T14 -> #REF! | U15: =T15/T4 -> #REF! | V15: =V9+V10+V11+V14 -> #REF! | W15: =V15/V4 -> #REF! | X15: =X9+X10+X11+X14 -> #REF! | Y15: =X15/X4 -> #REF! | Z15: =Z9+Z10+Z11+Z14 -> #REF! | AA15: =AA9+AA10+AA11+AA14 -> #REF! | AB15: =AB9+AB10+AB11+AB14 -> #REF! | AC15: =AC9+AC10+AC11+AC14 -> #REF! | AD15: =AD9+AD10+AD11+AD14 -> #REF! | AE15: =AE9+AE10+AE11+AE14 -> #REF! | AF15: =AF9+AF10+AF11+AF14 -> #REF! | AG15: =AG9+AG10+AG11+AG14 -> #REF! | ... AI15: =AI9+AI10+AI11+AI14 -> #REF!
A16: Всього операційний прибуток | B16: =B8-B15 -> #REF! | C16: =C8-C15 -> #REF! | D16: =D8-D15 -> #REF! | E16: =E8-E15 -> #REF! | F16: =F8-F15 -> #REF! | G16: =G8-G15 -> #REF! | H16: =H8-H15 -> 43349.25 | I16: =H16/H4 -> 0.22251067 | J16: =J8-J15 -> #REF! | K16: =J16/J4 -> #REF! | L16: =L8-L15 -> #REF! | M16: =L16/L4 -> #REF! | N16: =N8-N15 -> #REF! | O16: =N16/N4 -> #REF! | P16: =P8-P15 -> #REF! | Q16: =P16/P4 -> #REF! | R16: =R8-R15 -> #REF! | S16: =R16/R4 -> #REF! | T16: =T8-T15 -> #REF! | U16: =T16/T4 -> #REF! | V16: =V8-V15 -> #REF! | W16: =V16/V4 -> #REF! | X16: =X8-X15 -> #REF! | Y16: =X16/X4 -> #REF! | Z16: =Z8-Z15 -> #REF! | AA16: =AA8-AA15 -> #REF! | AB16: =AB8-AB15 -> #REF! | AC16: =AC8-AC15 -> #REF! | AD16: =AD8-AD15 -> #REF! | AE16: =AE8-AE15 -> #REF! | AF16: =AF8-AF15 -> #REF! | AG16: =AG8-AG15 -> #REF! | ... AI16: =AI8-AI15 -> #REF!
A17: Податок на прибуток | H17: =I17*H16 -> 9103.3425 | I17: 0.21
A18: Чистий прибуток | B18: =B16-B17 -> #REF! | C18: =C16-C17 -> #REF! | D18: =D16-D17 -> #REF! | E18: =E16-E17 -> #REF! | F18: =F16-F17 -> #REF! | G18: =F18/F6 -> #REF! | H18: =H16-H17 -> 34245.908 | I18: =H18/H4 -> 0.17578343 | J18: =J16-J17 -> #REF! | K18: =J18/J4 -> #REF! | L18: =L16-L17 -> #REF! | M18: =L18/L4 -> #REF! | N18: =N16-N17 -> #REF! | O18: =N18/N4 -> #REF! | P18: =P16-P17 -> #REF! | Q18: =P18/P4 -> #REF! | R18: =R16-R17 -> #REF! | S18: =R18/R4 -> #REF! | T18: =T16-T17 -> #REF! | U18: =T18/T4 -> #REF! | V18: =V16-V17 -> #REF! | W18: =V18/V4 -> #REF! | X18: =X16-X17 -> #REF! | Y18: =X18/X4 -> #REF! | Z18: =Z16-Z17 -> #REF! | AA18: =AA16-AA17 -> #REF! | AB18: =AB16-AB17 -> #REF! | AC18: =AC16-AC17 -> #REF! | AD18: =AD16-AD17 -> #REF! | AE18: =AE16-AE17 -> #REF! | AF18: =AF16-AF17 -> #REF! | AG18: =AG16-AG17 -> #REF! | ... AI18: =AI16-AI17 -> #REF!
A21: Амортизація та ОЗ
A22: Повернення інвестиці | I22: =38*73*2.5*30.5 -> 211517.5

Sheet Звіт по зп
A1: Зведений звіт про зарплату
A2: За період: з 01.05.2024 по 31.05.2024
A4: Співробітник | C4: Табельний номер | D4: Залишок на початок | E4: Оклад | F4: Аванс | G4: Відпрацьовано годин | H4: Почас. оплата | I4: Продажі (страви) | J4: Продажі (замовлення) | K4: Бонуси | L4: Аванси | N4: Нестача: | O4: Утримання | P4: Пр. нарахування | Q4: Їжа/Незакр.ст | R4: Інші розрахунки | S4: Разом | T4: Видані аванси | U4: Загальні виплати | V4: До видачі | W4: Залишок на кінець
A5: Barman
B6: KuksaD | C6: 135 | E6: 4 794,00 | G6: 8.975 | H6: 28.2 | L6: 6 077,10 | S6: 6 077,10 | U6: 6 077,10
B7: LabzovT | C7: 17 | D7: 5 428,50 | W7: 5 428,50
D9: 5 428,50 | E9: 4 794,00 | G9: 8.975 | H9: 28.2 | L9: 6 077,10 | S9: 6 077,10 | U9: 6 077,10 | W9: 5 428,50
A11: Kelner
B12: KovaliukV | C12: 16 | E12: 4 420,00 | H12: 26
B13: MarianchukI | C13: 175 | E13: 4 709,00 | G13: 6.9111111 | H13: 27.7 | I13: 82 414,37 | J13: 78 811,47 | L13: 4 594,52 | O13: -473.31 | S13: 4 121,21 | U13: 4 121,21
B14: SvyshchN | C14: 164 | E14: 4 709,00 | G14: 5.3756944 | H14: 27.7 | I14: 54 409,25 | J14: 52 667,15 | L14: 3 573,77 | O14: -0.47 | S14: 3 573,30 | U14: 3 573,30
B15: TsyhankovaD | C15: 165 | E15: 4 709,00 | G15: 8.6951389 | H15: 27.7 | I15: 107 146,22 | J15: 121 614,65 | L15: 5 780,55 | O15: -5.1 | S15: 5 775,45 | U15: 5 775,45
B16: VoronaY | C16: 199 | E16: 4 709,00 | G16: 0.9375 | H16: 27.7 | L16: 623.25 | S16: 623.25 | U16: 623.25
E18: 23 256,00 | G18: 21.919444 | H18: 136.8 | I18: 243 969,84 | J18: 253 093,27 | L18: 14 572,09 | O18: -478.88 | S18: 14 093,21 | U18: 14 093,21
A20: Kierownik Restauracji
B21: MekhtiievM | C21: 6 | E21: 5 950,00 | G21: 7.3631944 | H21: 35 | I21: 129.05 | L21: 10 377,50 | S21: 10 377,50 | U21: 10 377,50
E23: 5 950,00 | G23: 7.3631944 | H23: 35 | I23: 129.05 | L23: 10 377,50 | S23: 10 377,50 | U23: 10 377,50
A25: Kucharz działu zaopatrzenia
B26: LiubovP | C26: 50 | E26: 4 590,00 | G26: 8.71875 | H26: 27 | L26: 5 649,75 | O26: -578.43 | S26: 5 071,32 | U26: 5 071,32
B27: PyrohovYe | C27: 173 | D27: 3 747,75 | G27: 2.2770833 | L27: 1 557,55 | S27: 1 557,55 | V27: 1 557,55 | W27: 5 305,30
D29: 3 747,75 | E29: 4 590,00 | G29: 10.995833 | H29: 27 | L29: 7 207,30 | O29: -578.43 | S29: 6 628,87 | U29: 5 071,32 | V29: 1 557,55 | W29: 5 305,30
A31: Kucharz kuchni ciepłej - Rotisseur
B32: KovalD | C32: 11 | E32: 4 930,00 | G32: 10.478472 | H32: 29 | L32: 7 293,03 | O32: -66.03 | S32: 7 227,00 | U32: 7 227,00
B33: PyrohovYe | C33: 173 | D33: -3 747,75 | E33: 4 964,00 | G33: 7.3548611 | H33: 29.2 | L33: 5 154,29 | O33: -83.44 | S33: 5 070,85 | U33: 6 628,40 | V33: -1 557,55 | W33: -5 305,30
B34: TomchukD | C34: 51 | E34: 4 964,00 | G34: 8.9097222 | H34: 29.2 | L34: 6 243,95 | O34: -1 538,80 | S34: 4 705,15 | U34: 4 705,15
D36: -3 747,75 | E36: 14 858,00 | G36: 26.743056 | H36: 87.4 | L36: 18 691,27 | O36: -1 688,27 | S36: 17 003,00 | U36: 18 560,55 | V36: -1 557,55 | W36: -5 305,30
A38: Kucharz Kuchni Zimnej - Garde-manger
B39: BibikU | C39: 12 | E39: 4 845,00 | G39: 7.5180556 | H39: 28.5 | L39: 5 142,40 | O39: -368.65 | S39: 4 773,75 | U39: 4 773,75
B40: StarenkaK | C40: 23 | E40: 4 845,00 | G40: 8.6263889 | H40: 28.5 | L40: 5 900,52 | O40: -371.52 | S40: 5 529,00 | U40: 5 529,00
E42: 9 690,00 | G42: 16.144444 | H42: 57 | L42: 11 042,92 | O42: -740.17 | S42: 10 302,75 | U42: 10 302,75
A44: Menadżer Restauracji
B45: NikitinaY | C45: 179 | E45: 5 100,00 | G45: 7.425 | H45: 30 | I45: 17 757,53 | J45: 11 362,33 | L45: 5 355,00 | S45: 5 355,00 | U45: 5 355,00
B46: ShnyrenkoM | C46: 14 | E46: 5 100,00 | G46: 9.2138889 | H46: 30 | I46: 16 238,60 | J46: 13 581,42 | L46: 6 634,00 | O46: -4 | S46: 6 630,00 | U46: 6 630,00
E48: 10 200,00 | G48: 16.638889 | H48: 60 | I48: 33 996,13 | J48: 24 943,75 | L48: 11 989,00 | O48: -4 | S48: 11 985,00 | U48: 11 985,00
A50: Sous Chef
B51: ProkhorchukP | C51: 47 | E51: 5 270,00 | G51: 6.6409722 | H51: 31 | L51: 4 940,89 | O51: -413.17 | S51: 4 527,72 | U51: 4 527,72
E53: 5 270,00 | G53: 6.6409722 | H53: 31 | L53: 4 940,89 | O53: -413.17 | S53: 4 527,72 | U53: 4 527,72
A55: Sprzątacz sali restauracyjnej
B56: YatsyshynL | C56: 151 | E56: 4 709,00 | G56: 5.7361111 | H56: 27.7 | L56: 3 813,36 | O56: -503.21 | S56: 3 310,15 | U56: 3 310,15
E58: 4 709,00 | G58: 5.7361111 | H58: 27.7 | L58: 3 813,36 | O58: -503.21 | S58: 3 310,15 | U58: 3 310,15
...

Sheet Продажі червень
B1: Червень
B3: Загальні продажі | C3: 335231 | D3: =C3/C3 -> 1 | F3: Продажі бар | G3: =SUM(G4:G10) -> 89900 | H3: 1
B4: Кухня всього | C4: =C6+C5 -> 240996 | D4: =C4/C3 -> 0.71889533 | F4: Вино | G4: 11019 | H4: =G4/$G$3 -> 0.12256952
B5: Кухня (без сніданків) | C5: 209555 | D5: =C5/C3 -> 0.62510627 | F5: Вино розлив | G5: 8518 | H5: =G5/$G$3 -> 0.094749722
B6: Сніданки окремо | C6: 31441 | D6: =C6/C3 -> 0.093789059 | F6: Міцний алкоголь | G6: 2364 | H6: =G6/$G$3 -> 0.026295884
B7: Бар всього | C7: =C8+C9+C10+C11+C12 -> 90013 | D7: =C7/C3 -> 0.26851037 | F7: Коктейлі | G7: 18722 | H7: =G7/$G$3 -> 0.20825362
B8: Бар ба | C8: 43155 | D8: =C8/C3 -> 0.12873213 | F8: Пиво | G8: 6540 | H8: =G8/$G$3 -> 0.072747497
B9: Алкоголь 4,5-18% | C9: 24160 | D9: =C9/C3 -> 0.072069707 | F9: Б/а напої | G9: 16575 | H9: =G9/$G$3 -> 0.18437152 | I9: Б/а напої
B10: Алкоголь вище 18% | C10: 15438 | D10: =C10/C3 -> 0.046051827 | F10: Кава і чай | G10: 26162 | H10: =G10/$G$3 -> 0.29101224 | I10: =SUM(H9:H10) -> 0.47538376
B11: Алкголь до 4,5% | C11: 6540 | D11: =C11/C3 -> 0.019508936
B12: Алкоголь (Clover Club vol.3.0 Ron Dark Calados) | C12: 720 | D12: =C12/C3 -> 0.0021477727
B13: Услуга гастрономічна (доставки чи ще щось) | C13: 4212 | D13: =C13/C3 -> 0.01256447
B17: Звіт про продажі з 01.06.2024по 30.06.2024
A18: Підкатегорія | B18: Категорія | C18: Елемент номенклатури | D18: Середня ціна без вирахування знижок, zl. | E18: Середня ціна, zl. | F18: Кількість | G18: Виторг без вирахування знижок, zl. | H18: Виторг, zl. | I18: Валовий прибуток, zl. | J18: Націнка, % | K18: Валовий прибуток без ПДВ, zl. | L18: % від виторгу
A19: Коктейль | B19: Alkohol | C19: Clover Club vol.3.0 | D19: 35 | E19: 35 | F19: 20 | G19: 700 | H19: 700 | I19: 607.3 | J19: 655.12 | K19: 476.42 | L19: 0.21
B20: Alkohol | C20: Ron Dark Calados | D20: 10 | E20: 10 | F20: 2 | G20: 20 | H20: 20 | I20: 13.89 | J20: 227.33 | K20: 10.15 | L20: 0.01
A21: Пиво | B21: Alkohol do 4,5% | C21: WRCLW Lager 500ml | D21: 17 | E21: 17 | F21: 140 | G21: 2380 | H21: 2380 | I21: 1518.01 | J21: 176.11 | K21: 1072.94 | L21: 0.71
A22: Пиво | B22: Alkohol do 4,5% | C22: WRCLW Pszeniczny 500ml | D22: 17 | E22: 17 | F22: 122 | G22: 2074 | H22: 2074 | I22: 1341.07 | J22: 182.97 | K22: 953.23 | L22: 0.62
A23: Пиво | B23: Alkohol do 4,5% | C23: WRCLW Bezalkoholowy 500ml | D23: 16 | E23: 16 | F23: 63 | G23: 1008 | H23: 1008 | I23: 634.77 | J23: 170.07 | K23: 446.29 | L23: 0.3
A24: Пиво | B24: Alkohol do 4,5% | C24: American Ipa Browar Stu Mostów 500 ml | D24: 22 | E24: 22 | F24: 27 | G24: 594 | H24: 594 | I24: 388.8 | J24: 189.47 | K24: 277.75 | L24: 0.18
A25: Пиво | B25: Alkohol do 4,5% | C25: Chocolate stout Stu Mostow 500 ml | D25: 22 | E25: 22 | F25: 22 | G25: 484 | H25: 484 | I25: 316.45 | J25: 188.87 | K25: 225.97 | L25: 0.14
A26: Коктейль | B26: Alkohol od 4,5% do 18% | C26: Aperol Spritz 200 ml | D26: 34.24 | E26: 34.24 | F26: 135 | G26: 4623 | H26: 4623 | I26: 3573.69 | J26: 340.58 | K26: 2709.25 | L26: 1.38
A27: Вино розлив | B27: Alkohol od 4,5% do 18% | C27: Marlborough sun sauvignon blanc 125ml. | D27: 27 | E27: 27 | F27: 106 | G27: 2862 | H27: 2862 | I27: 2116.3 | J27: 283.8 | K27: 1581.13 | L27: 0.85
A28: Вино розлив | B28: Alkohol od 4,5% do 18% | C28: Ca`Val extra Dry Prosecco Treviso 125ml | D28: 22 | E28: 22 | F28: 86 | G28: 1892 | H28: 1892 | I28: 1441.81 | J28: 320.27 | K28: 1088.03 | L28: 0.56
A29: Вино розлив | B29: Alkohol od 4,5% do 18% | C29: Chateau ste Michelle Riesling Ava Columbia Valley 125ml | D29: 35 | E29: 35 | F29: 26 | G29: 910 | H29: 910 | I29: 715.4 | J29: 367.63 | K29: 545.28 | L29: 0.27
A30: Вино | B30: Alkohol od 4,5% do 18% | C30: b_Ca`Val extra Dry Prosecco Treviso 750ml | D30: 115 | E30: 115 | F30: 21 | G30: 2415 | H30: 2415 | I30: 1755.39 | J30: 266.13 | K30: 1303.82 | L30: 0.72
A31: Вино розлив | B31: Alkohol od 4,5% do 18% | C31: Richlad Black Shiraz Riverina 125ml | D31: 30 | E31: 30 | F31: 20 | G31: 600 | H31: 600 | I31: 495.3 | J31: 473.07 | K31: 383.1 | L31: 0.18
A32: Вино розлив | B32: Alkohol od 4,5% do 18% | C32: Borgo Savaian Aransat Vino Bianco D`italia 125ml | D32: 32 | E32: 32 | F32: 20 | G32: 640 | H32: 640 | I32: 469.13 | J32: 274.55 | K32: 349.48 | L32: 0.19
... A126: Кава | B126: B/A | C126: Matca tonic | D126: 20.27 | E126: 20.27 | F126: 11 | G126: 223 | H126: 223 | I126: 163.93 | J126: 277.52 | K126: 122.23 | L126: 0.07
B127: B/A | C127: Sour mix | D127: 5 | E127: 5 | F127: 9 | G127: 45 | H127: 45 | I127: 40.39 | J127: 876.14 | K127: 37.06 | L127: 0.01
A128: Кава | B128: B/A | C128: Ice Matcha | D128: 20.33 | E128: 20.33 | F128: 9 | G128: 183 | H128: 183 | I128: 145.84 | J128: 392.47 | K128: 111.62 | L128: 0.05
A129: Сік | B129: B/A | C129: Seler wyciskany sok 300 ml. | D129: 21.14 | E129: 21.14 | F129: 8.666 | G129: 183.16 | H129: 183.16 | I129: 183.16 | J129: 0 | K129: 169.6 | L129: 0.05
A130: Сік | B130: B/A | C130: Sok wiśnia 250 ml. | D130: 15.63 | E130: 15.63 | F130: 8 | G130: 125 | H130: 125 | I130: 80.9 | J130: 183.45 | K130: 71.63 | L130: 0.04
A131: Чай | B131: B/A | C131: Herbata Detox 400ml | D131: 18.57 | E131: 18.57 | F131: 7 | G131: 130 | H131: 130 | I131: 125.7 | J131: 2923.26 | K131: 101.4 | L131: 0.04
A132: б/а | B132: B/A | C132: Tonic Henry | D132: 15 | E132: 15 | F132: 7 | G132: 105 | H132: 105 | I132: 105 | J132: 0 | K132: 85.39 | L132: 0.03
A133: Кава | B133: B/A | C133: Karamel do kawy | D133: 3 | E133: 3 | F133: 4 | G133: 12 | H133: 12 | I133: 12 | J133: 0 | K133: 11.12 | L133: 0
B134: B/A | C134: Przelew | D134: 16 | E134: 16 | F134: 3 | G134: 48 | H134: 48 | I134: 44.84 | J134: 1418.99 | K134: 35.87 | L134: 0.01
A135: Сік | B135: B/A | C135: Sok jabłkowy 1L. | D135: 20 | E135: 20 | F135: 1 | G135: 20 | H135: 20 | I135: 12.6 | J135: 170.27 | K135: 11.12 | L135: 0.01
B136: Kuchnia | C136: Ukraiński barszcz z boczkiem. | D136: 48 | E136: 46.85 | F136: 391 | G136: 18768 | H136: 18319.2 | I136: 13617.5 | J136: 289.63 | K136: 12260.56 | L136: 5.46
B137: Kuchnia | C137: Kotlet po kijowsku. | D137: 58 | E137: 55.76 | F137: 364 | G137: 21112 | H137: 20297.1 | I137: 17647.91 | J137: 666.16 | K137: 16144.42 | L137: 6.05
...

Sheet Погодинний виторг червень ісход
A1: Погодинний виторг
A2: Назва ресторану: NAI WROCŁAW
A3: Період: з 01.06.2024 по 30.06.2024
C4: Загальний підсумок
A5: Обліковий день | B5: Година закриття | C5: Кількість гостей | D5: Сума без знижки, zl. | F5: Сума зі знижкою, zl. | G5: Чеків
A6: 45444 | B6: 9 | C6: 4 | D6: 223.5 | F6: 223.5 | G6: 4 | I6: СБ
B7: 10 | C7: 3 | D7: 105 | F7: 105 | G7: 2
B8: 11 | C8: 7 | D8: 686 | F8: 686 | G8: 3
B9: 12 | C9: 4 | D9: 480 | F9: 480 | G9: 4
C10: =SUM(C6:C9) -> 18 | D10: =SUM(D6:D9) -> 1494.5 | F10: =SUM(F6:F9) -> 1494.5 | G10: =SUM(G6:G9) -> 13
A11: 01.06.2024 Total | C11: 111 | D11: 16050.5 | F11: 15830.5 | G11: 69
A12: 45445 | B12: 10 | C12: 3 | D12: 347 | F12: 347 | G12: 3 | I12: НД
B13: 11 | C13: 10 | D13: 1290 | F13: 1210 | G13: 9
B14: 12 | C14: 9 | D14: 810 | F14: 810 | G14: 8
A15: 02.06.2024 Total | C15: 115 | D15: 15961 | F15: 15450 | G15: 85
A16: 45446 | B16: 9 | C16: 1 | D16: 66 | F16: 66 | G16: 1 | I16: ПН
B17: 10 | C17: 1 | D17: 139 | F17: 85 | G17: 1
B18: 12 | C18: 6 | D18: 2179 | F18: 2145.1 | G18: 5
A19: Всього на сніданках | C19: =C16+C17+C18 -> 8 | D19: =D16+D17+D18 -> 2384 | E19: =D19/D20 -> 0.50099821 | F19: =F16+F17+F18 -> 2296.1 | G19: =G16+G17+G18 -> 7 | H19: =G19/G20 -> 0.25
A20: 03.06.2024 Total | C20: 33 | D20: 4758.5 | F20: 4196.4 | G20: 28
A21: 45447 | B21: 9 | C21: 1 | D21: 86 | F21: 86 | G21: 1 | I21: ВТ
B22: 10 | C22: 4 | D22: 212 | F22: 212 | G22: 3
B23: 11 | C23: 6 | D23: 289 | F23: 245 | G23: 5
B24: 12 | C24: 5 | D24: 302 | F24: 302 | G24: 3
A25: Всього на сніданках | C25: =C22+C23+C24+C21 -> 16 | D25: =D22+D23+D24+D21 -> 889 | E25: =D25/D26 -> 0.16032462 | F25: =F22+F23+F24+F21 -> 845 | G25: =G22+G23+G24+G21 -> 12 | H25: =G25/G26 -> 0.35294118
A26: 04.06.2024 Total | C26: 57 | D26: 5545 | F26: 5299.2 | G26: 34
A27: 45448 | B27: 9 | C27: 3 | D27: 120 | F27: 120 | G27: 1 | I27: СР
B28: 10 | C28: 3 | D28: 65 | F28: 65 | G28: 2
B29: 11 | C29: 3 | D29: 148 | F29: 148 | G29: 3
B30: 12 | C30: 1 | D30: 17 | F30: 17 | G30: 1
A31: Всього на сніданках | C31: =C27+C28+C29+C30 -> 10 | D31: =D27+D28+D29+D30 -> 350 | E31: =D31/D32 -> 0.039432177 | F31: =F27+F28+F29+F30 -> 350 | G31: =G27+G28+G29+G30 -> 7 | H31: =G31/G32 -> 0.1372549
A32: 05.06.2024 Total | C32: 89 | D32: 8876 | F32: 8386.15 | G32: 51
A33: 45449 | B33: 10 | C33: 4 | D33: 144 | F33: 144 | G33: 3 | I33: ЧТ
B34: 12 | C34: 6 | D34: 203 | F34: 182 | G34: 5
A35: Всього на сніданках | C35: =C33+C34 -> 10 | D35: =D33+D34 -> 347 | E35: =D35/D36 -> 0.030200174 | F35: =F33+F34 -> 326 | G35: =G33+G34 -> 8 | H35: =G35/G36 -> 0.14285714
A36: 06.06.2024 Total | C36: 95 | D36: 11490 | F36: 10969.2 | G36: 56
A37: 45450 | B37: 9 | C37: 2 | D37: 38 | F37: 38 | G37: 1
B38: 10 | C38: 4 | D38: 303.5 | F38: 303.5 | G38: 3
B39: 11 | C39: 7 | D39: 366 | F39: 366 | G39: 4
B40: 12 | C40: 2 | D40: 148 | F40: 148 | G40: 1
...

Sheet Погодинний виторг червень
A1: Погодинний виторг
B2: Кількість гостей | C2: % гостей на сніданках від загального в день | D2: Сума зі знижкою, zl. | E2: % продажу сніданків від оберту в день | F2: Чеків | G2: % чеків сніданків від загального в день | I2: Час відкриття першого чеку
A3: 45446 | H3: ПН | I3: 9.16
A4: Всього на сніданках | B4: 8 | C4: =B4/B5 -> 0.24242424 | D4: =2296.1-1890 -> 406.1 | E4: =D4/D5 -> 0.096773425 | F4: 7 | G4: 0.25
A5: Всього за день | B5: 33 | D5: 4196.4 | F5: 28
A6: 45447 | H6: ВТ | I6: 45391
A7: Всього на сніданках | B7: 16 | C7: =B7/B8 -> 0.28070175 | D7: 845 | E7: =D7/D8 -> 0.15945803 | F7: 12 | G7: 0.35294118
A8: Всього за день | B8: 57 | D8: 5299.2 | F8: 34
A9: 45448 | H9: СР | I9: 45452
A10: Всього на сніданках | B10: 10 | C10: =B10/B11 -> 0.11235955 | D10: 350 | E10: =D10/D11 -> 0.041735481 | F10: 7 | G10: 0.1372549
A11: Всього за день | B11: 89 | D11: 8386.15 | F11: 51
A12: 45449 | H12: ЧТ | I12: 45514
A13: Всього на сніданках | B13: 10 | C13: =B13/B14 -> 0.10526316 | D13: 326 | E13: =D13/D14 -> 0.029719578 | F13: 8 | G13: 0.14285714
A14: Всього за день | B14: 95 | D14: 10969.2 | F14: 56
A15: 45453 | H15: ПН | I15: 9.17
A16: Всього на сніданках | B16: 17 | C16: =B16/B17 -> 0.30357143 | D16: 1366.47 | E16: =D16/D17 -> 0.27310992 | F16: 13 | G16: 0.325
A17: Всього за день | B17: 56 | D17: 5003.37 | F17: 40
A18: 45454 | H18: ВТ | I18: 11.20
A19: Всього на сніданках | B19: 11 | C19: =B19/B20 -> 0.14285714 | D19: 906.25 | E19: =D19/D20 -> 0.097365622 | F19: 7 | G19: 0.15555556
A20: Всього за день | B20: 77 | D20: 9307.7 | F20: 45
A21: 45455 | H21: СР | I21: 9.31
A22: Всього на сніданках | B22: 17 | C22: =B22/B23 -> 0.22077922 | D22: 1234.5 | E22: =D22/D23 -> 0.16706815 | F22: 11 | G22: 0.28205128
A23: Всього за день | B23: 77 | D23: 7389.2 | F23: 39
A24: 45456 | H24: ЧТ | I24: 9.23
A25: Всього на сніданках | B25: 12 | C25: =B25/B26 -> 0.15584416 | D25: 798.9 | E25: =D25/D26 -> 0.11668139 | F25: 9 | G25: 0.18367347
A26: Всього за день | B26: 77 | D26: 6846.85 | F26: 49
A27: 45460 | H27: ПН | I27: 9.17
A28: Всього на сніданках | B28: 14 | C28: =B28/B29 -> 0.23333333 | D28: 1501 | E28: =D28/D29 -> 0.22932661 | F28: 10 | G28: 0.27027027
A29: Всього за день | B29: 60 | D29: 6545.25 | F29: 37
A30: 45461 | H30: ВТ | I30: 10.37
A31: Всього на сніданках | B31: 6 | C31: =B31/B32 -> 0.082191781 | D31: 570.6 | E31: =D31/D32 -> 0.037459626 | F31: 5 | G31: 0.11363636
A32: Всього за день | B32: 73 | D32: 15232.4 | F32: 44
A33: 45462 | H33: СР | I33: 45513
A34: Всього на сніданках | B34: 16 | C34: =B34/B35 -> 0.25396825 | D34: 918.05 | E34: =D34/D35 -> 0.15382489 | F34: 11 | G34: 0.26190476
A35: Всього за день | B35: 63 | D35: 5968.15 | F35: 42
A36: 45463 | H36: ЧТ | I36: 9.16
A37: Всього на сніданках | B37: 22 | C37: =B37/B38 -> 0.275 | D37: 1360.05 | E37: =D37/D38 -> 0.13484065 | F37: 11 | G37: 0.26190476
A38: Всього за день | B38: 80 | D38: 10086.35 | F38: 42
A39: 45467 | H39: ПН | I39: 45635
A40: Всього на сніданках | B40: 15 | C40: =B40/B41 -> 0.27272727 | D40: 1398.35 | E40: =D40/D41 -> 0.25304281 | F40: 12 | G40: 0.27906977
...

Sheet Аналіз конкурентів
